Workbook

Sheet DistilBERT_Response
A1: PromptID | B1: English | C1: Hindi | D1: EN_Sentiment_Label | E1: EN_Sentiment_Score | F1: HI_Sentiment_Label | G1: HI_Sentiment_Score
A2: PO1 | B2: So my therapist recommended to me that I should post on reddit. I'm currently 18 but the story starts when I was 16 in the summer of 2019. I live in the UK and it was the day I received my gcses. I did really well in them and I got 8 A*s and 2 As after a year of hard work and effort. I was at my highest point and I couldn't believe it. The day after however, my cousin tragically passed away in a freak accident in Mexico that should never have happened and I was suddenly thrown into a whirlwind of people grieving around me and panic surrounding how they were going to get his body back and many other things. Initially I thought I was doing okay but a week and a half later, I had my first panic attack. It was terrifying, I genuinely thought I was having a heart attack and that I was going to die. This was my first introduction into my hypochondria and anxiety. For the remainder of the summer I was in a constant state of anxiety and panic - struggling to sleep, eat and petrified about death. During the gcses I was also getting close to a girl who was in my year (we'll call her Anna). However during the early summer Anna got with another guy and things died out after she told me we're no longer on things. After things didn't work out with that guy she messaged me again saying that she wanted to reset things with me (little to my knowledge she was also getting close to another guy during this time). When I went back to school I was still suffering from anxiety and panic - I was quite, unable to speak to anyone from how bad it was. During the first 2 weeks, I was getting close with Anna again and eventually we started to go out. Initially things were going good, my anxiety started to die down and I no longer was having panic attacks. However soon the anxiety returned and manifested itself in different ways that weren't as noticeable with paranoia, fear and depressive episodes due to the fact that she wasn't exactly loyal in the past. Eventually with lockdown things started to get bad. She naturally has quite an abrasive personality but it usually was counterbalanced by her more tender side. However that started to change over lockdown and she started to become very toxic towards me - calling me unattractive, not her type, pathetic etc. This carried on and culminated in her out right treating me like shit where she'd refuse to even speak to me if she didn't like the restaurant I took her to on a date. There are way more examples and stories of this that I can give - even the time she sexually assaulted me which I don't want to get into. But I stayed, I loved her and being with her was the thing that helped me stop being constantly an anxious and nervous wreck. I saw her as the person that I went out with at the start not the person she became. Eventually I couldn't bare it anymore and I broke up with her in October but now the skeletons in my closest have opened and all the feelings I had have returned. For the last 2 months I haven't been eating or sleeping well and I've been constantly anxious. I now also borderline have a panic attack whenever I see her at school too. I'm now seeing a therapist but it took a month - I didn't think I needed help, it can be scary but it can honestly be the best decision you can make. I'm more optimistic about things now and I can see the light at the end of the tunnel. | C2: इसलिए मेरे चिकित्सक ने मुझे सलाह दी कि मुझे रेडिट पर पोस्ट करना चाहिए । मैं वर्तमान में 18 साल का हूँ लेकिन कहानी शुरू होती है जब मैं 2019 की गर्मियों में 16 साल का था । मैं यूके में रहता हूँ और यह वह दिन था जब मुझे अपने जी. सी. एस. मिले । मैंने वास्तव में उनमें अच्छा प्रदर्शन किया और मुझे 8 ए. एस. और 2 मिले क्योंकि एक साल की कड़ी मेहनत और प्रयास के बाद । मैं अपने उच्चतम बिंदु पर था और मुझे इस पर विश्वास नहीं हो रहा था । हालांकि अगले दिन मेरे चचेरे भाई का दुखद रूप से मेक्सिको में एक अजीब दुर्घटना में निधन हो गया जो कभी नहीं होना चाहिए था और मुझे अचानक अपने आस - पास शोकाकुल लोगों के बवंडर में फेंक दिया गया था और इस बारे में घबराया गया था कि वे कैसे उसके शरीर को वापस लाने जा रहे थे और कई अन्य चीजें । शुरू में मुझे लगा कि मैं ठीक कर रहा था लेकिन डेढ़ हफ्ते बाद मुझे पहला पैनिक अटैक आया था । मुझे लगा कि वास्तव में मुझे दिल का दौरा पड़ रहा था और यह मेरी पहली चिंता थी कि मैं पहले हायपोक्रिया में मर रहा था । बाकी गर्मियों के लिए मैं लगातार चिंता और घबराहट की स्थिति में था - सोने के लिए संघर्ष कर रहा था - खाने के लिए और मृत्यु के बारे में भयभीत था । जी. सी. एस. ई. के दौरान मैं एक लड़की के करीब भी जा रहा था जो मेरे वर्ष में थी ( हम उसे अन्ना कहेंगे ) । हालाँकि गर्मियों की शुरुआत में एना एक और लड़के के साथ मिल गई और चीजें खत्म हो गईं जब उसने मुझसे कहा कि हम अब चीजों पर नहीं हैं । उस आदमी के साथ चीजें ठीक नहीं होने के बाद उसने मुझे फिर से संदेश भेजा कि वह मेरे साथ चीजों को फिर से सेट करना चाहती है ( मेरे ज्ञान के अनुसार वह इस दौरान दूसरे लड़के के भी करीब हो रही थी ) । जब मैं स्कूल वापस गया तो मैं अभी भी चिंता और दहशत से पीड़ित था - मैं किसी से भी बात करने में असमर्थ था कि यह कितना बुरा था । पहले 2 हफ्तों के दौरान मैं फिर से अन्ना के करीब आ रहा था और आखिरकार हम बाहर जाने लगे । शुरू में मेरी चिंता कम होने लगी थी । लेकिन जल्द ही चिंता वापस आ गई और खुद को अलग - अलग तरीकों से प्रकट कर दिया जो अतीत में बिल्कुल वफादार नहीं होने के कारण डर और अवसादग्रस्तता के साथ ध्यान देने योग्य नहीं थे । आखिरकार लॉकडाउन के साथ चीजें खराब होने लगीं । स्वाभाविक रूप से उनका व्यक्तित्व काफी घर्षक था लेकिन यह आमतौर पर उनके अधिक कोमल पक्ष से असंतुलित था । हालाँकि यह लॉकडाउन के बाद बदलने लगा और वह मेरे प्रति बहुत विषाक्त होने लगी - मुझे अनाकर्षक कहने लगी - अपने प्रकार की दयनीय आदि नहीं । यह जारी रहा और उसके मेरे साथ सही व्यवहार करने में समाप्त हो गया, जहां वह मुझसे बात करने से भी इनकार कर देती थी, अगर वह पसंद नहीं करती थी कि जिस रेस्तरां में मैं उसे डेट पर ले गई थी । इसके और भी उदाहरण और कहानियां हैं जो मैं दे सकती हूं - उस समय भी जब उसने मेरा यौन उत्पीड़न किया था जिसे मैं शामिल नहीं करना चाहती थी । लेकिन मैं उससे प्यार करती थी और उसके साथ रहने से मुझे लगातार चिंतित और घबराए हुए होने से रोकने में मदद मिली । मैंने उसे उस व्यक्ति के रूप में देखा जिसके साथ मैं शुरू में बाहर गई थी न कि वह व्यक्ति जो वह बन गई थी । आखिरकार मैं इसे और बर्फ़ नहीं कर सकी और अक्टूबर में मैंने उसके साथ ब्रेकअप कर लिया, लेकिन अब मेरे सबसे करीबी कंकाल खुल गए हैं और सभी भावनाएँ वापस आ गई हैं । पिछले 2 महीनों से मैं खा नहीं रही हूं या अच्छी तरह से सो नहीं रही हूं और मैं लगातार चिंतित हूं । अब जब भी मैं उसे स्कूल में देखती हूं तो मुझे भी पैनिक अटैक होता है । मैं अब एक चिकित्सक को देख रही हूं लेकिन इसमें एक महीना लग गया - मुझे नहीं लगता था कि मुझे मदद की ज़रूरत है क्योंकि यह डरावना हो सकता है लेकिन यह ईमानदारी से सबसे अच्छा निर्णय हो सकता है । मैं अब चीजों के बारे में अधिक आशावादी हूं और मैं सुरंग के अंत में रोशनी देख सकती हूं । | D2: NEGATIVE | E2: 0.603028 | F2: NEGATIVE | G2: 0.92538089
A3: PO2 | B3: Hey all! I'd like to start this thread to maybe help each other check in on 'filling the cup.' My anxiety embeds itself as relationship anxiety and in-home anxiety, where being home too much makes me intensely anxious, feeling totally empty, useless and lonely. I have a hard time just hanging out (you can imagine what 9 months of COVID has done to me in this regard.) I've started making a daily practice of creating a 'Ways to Fill My Cup' list, so that I feel less empty and anxious. It's helping me A LOT to check out which things make me feel most supported and calm. I make a list starting in the morning and add to it if I do other positive things during the day. Example: Yesterday I had no plans, and the impending day of loneliness at home was looming dark and large. So my "Fill My Cup" list ended up pretty long. On it were things like: Finally doing my dishes, putting on the Chillhop ambient sound spotify playlist which was amazing for my busy mind, unpacking all of my Christmas items which makes my space feel more clean, spending time on my skin and teeth care which I sometimes neglect and then feel bad about, watching one hour of a comforting show, calling one friend, scrubbing neglected kitchen/bathroom spots with clorox wipes, watching funny animal videos, and more. This seems like a normal day of tasking, but since I also have ADHD, I often neglect things or am not consciously 'checked in' to doing them, so it has no impact on my emotional wellbeing. Writing these items down so that I could SEE that my day wasn't totally 'wasted' in 'emptiness' was a huge deal for me. I spent time being productive and also time just being my own friend. Adding to it throughout the day kept me focused on the actual imagery of filling up my cup. My mind stayed relatively calm throughout. Does anyone else engage in a similar practice? If not, do you think it might help you? Let's talk!! | C3: अरे सभी अद्भुत लोग, मैं इस धागे को शुरू करना चाहता हूं ताकि शायद एक - दूसरे को'कप भरने'में मदद मिल सके । मेरी चिंता खुद को रिश्ते की चिंता और घर में चिंता के रूप में जोड़ती है । जहाँ घर में बहुत अधिक होने से मुझे बहुत अधिक चिंता होती है । मैं पूरी तरह से खाली और अकेला महसूस करता हूं । मुझे बस बाहर घूमना मुश्किल होता है ( आप कल्पना कर सकते हैं कि कोविड के 9 महीनों ने इस संबंध में मेरे साथ क्या किया है । मैंने'मेरे कप को भरने के तरीके'की सूची बनाने का दैनिक अभ्यास करना शुरू कर दिया है ताकि मैं कम खाली और चिंतित महसूस करूं । इससे मुझे यह देखने में बहुत मदद मिल रही है कि कौन सी चीजें मुझे सबसे अधिक समर्थित और शांत महसूस कराती हैं । मैं सुबह से एक सूची बनाता हूं और अगर मैं दिन के दौरान अन्य सकारात्मक चीजें करता हूं तो इसमें जोड़ता हूं । उदाहरण के लिएः कल मेरी कोई योजना नहीं थी और घर में अकेलेपन का आने वाला दिन अंधेरा और बड़ा हो रहा था । इसलिए मेरी " मेरे कप को भरें " सूची काफी लंबी हो गई । इस पर कुछ चीजें थीं जैसेः अंत में मेरे व्यंजन बनाना - चिलहॉप परिवेश ध्वनि स्पॉटिफाई प्लेलिस्ट जो मेरे व्यस्त दिमाग के लिए अद्भुत था - मेरी क्रिसमस की सभी वस्तुओं को खोलना जो मेरी जगह को अधिक स्वच्छ महसूस कराता है - मेरी त्वचा और दांतों की देखभाल पर समय बिताना जो मैं कभी - कभी उपेक्षा करता हूं और फिर एक घंटे के आरामदायक शो को देखने के बारे में बुरा महसूस करता हूं - एक दोस्त को बुलाना - उपेक्षित रसोईघर / बाथरूम के धब्बों को स्क्रब करना - क्लोरॉक्स वाइप्स के साथ - साथ मजेदार जानवरों के वीडियो देखना - और बहुत कुछ । यह काम करने का एक सामान्य दिन लगता है लेकिन चूंकि मेरे पास एडीएचडी भी है, इसलिए मैं अक्सर चीजों की उपेक्षा करता हूं या जानबूझकर उनकी जांच नहीं करता हूं - ऐसा करने से मेरी भावनात्मक भलाई पर कोई प्रभाव नहीं पड़ता है । इन वस्तुओं को लिख कर ताकि मैं देख सकूं कि मेरा दिन'खालीपन'में पूरी तरह से'बर्बाद'नहीं हुआ था, यह मेरे लिए एक बहुत बड़ा सौदा था । मैंने उत्पादक होने में समय बिताया और साथ ही समय सिर्फ अपना खुद का दोस्त होने में भी बिताया । पूरे दिन इसके साथ जुड़ने से मेरा ध्यान अपने कप को भरने की वास्तविक कल्पना पर केंद्रित रहा । मेरा मन पूरे समय अपेक्षाकृत शांत रहा । क्या कोई और इसी तरह के अभ्यास में संलग्न है । | D3: POSITIVE | E3: 0.79512846 | F3: NEGATIVE | G3: 0.93195212
A4: PO3 | B4: When does it come? I made so many silly posts ruminating about awkwardness talking to her, me not wanting to hang out cuz anxiety that I tried hiding, if I was being weird, if I was texting too much because she didn’t reply on a few, the typical over analyzing. I’m high and I just realized while obviously none of that matters my fear is being vulnerable because entering a relationship is an intimate thing and you are sharing your life with someone special apparently. I’ve never really been in a relationship but I’ve realized I’ve been feeling a loneliness my friends can’t help me with. Just speaking from the heart I guess. | C4: यह कब होता है, मैं उससे अजीबता के बारे में अफवाह करते हुए इतने सारे मूर्ख पोस्ट बनाती हूँ, क्योंकि मैं इस चिंता को छिपाना नहीं चाहती थी कि अगर मैं अजीब हो रही थी तो मैं छिपाने की कोशिश कर रही थी, अगर मैं बहुत अधिक संदेश भेज रही थी क्योंकि उसने कुछ पर जवाब नहीं दिया था, तो सामान्य रूप से अधिक विश्लेषण करना । मैं उच्च हूँ और मुझे एहसास हुआ कि जाहिर है कि इनमें से कोई भी मायने नहीं रखता है कि मेरा डर कमजोर हो रहा है क्योंकि रिश्ते में प्रवेश करना एक अंतरंग बात है और आप अपने जीवन को किसी विशेष व्यक्ति के साथ साझा कर रहे हैं । मैं वास्तव में कभी भी किसी रिश्ते में नहीं रही हूं, लेकिन मुझे एहसास हुआ कि मैं एक अकेलापन महसूस कर रही हूं जिसमें मेरे दोस्त मेरी मदद नहीं कर सकते हैं । बस दिल से बात करते हुए मुझे लगता है । | D4: NEGATIVE | E4: 0.99705756 | F4: NEGATIVE | G4: 0.9224503
A5: PO4 | B5: I've been working at a job (~6 months so far) that requires me to communicate on the phone effectively, and know a lot about the details my job (which a lot comes from experience). Before this job, I had no phone experience and I had extreme phone anxiety (I probably have social anxiety which contributes greatly to it). It took me a lot of effort to push past my anxiety and start using the phone. I still have anxiety but I am better at dealing with it. Anyways, I was trying to help a customer, and I was feeling extra nice so I put in extra effort for this woman. Unfortunately, I wasn't experienced in one area of my job so I couldn't answer a couple of her questions. The customer said that she was tired of me not being able to answer her questions and that it is sort of ridiculous. She didn't thank me for the previous work I did either. I told her I would get her a more experienced person. I get it, I'm supposed to be an expert at my job, but damn it really crippled my confidence to hear her say that. I felt like I was working hard, but, in that moment I felt like it was meaningless. I put in effort and was rewarded with a negative experience and lots of negative feelings. The experience after the phone call was just me feeling sad and overwhelmed. I drove home after work and almost cried lol. I feel pathetic that I can't handle angry customers and I am second-guessing if this job is really going to work for me. I don't know what I want from this. No one will read it anyways. -Bird | C5: मैं एक नौकरी पर काम कर रहा हूँ ( अब तक 6 महीने ) जिसके लिए मुझे फोन पर प्रभावी ढंग से संवाद करने की आवश्यकता होती है और मुझे अपनी नौकरी के विवरण के बारे में बहुत कुछ जानने की आवश्यकता होती है ( जो बहुत कुछ अनुभव से आता है ) । इस नौकरी से पहले मुझे फोन का कोई अनुभव नहीं था और मुझे अत्यधिक फोन चिंता थी ( मुझे शायद सामाजिक चिंता है जो इसमें बहुत योगदान देती है ) । मुझे अपनी चिंता को दूर करने और फोन का उपयोग शुरू करने में बहुत प्रयास करना पड़ा । मुझे अभी भी चिंता है लेकिन मैं इससे निपटने में बेहतर हूं । वैसे भी मैं एक ग्राहक की मदद करने की कोशिश कर रहा था और मैं अधिक अच्छा महसूस कर रहा था इसलिए मैंने इस महिला के लिए अतिरिक्त प्रयास किया । दुर्भाग्य से मैं अपनी नौकरी के एक क्षेत्र में अनुभवी नहीं था इसलिए मैं उसके कुछ प्रश्नों का उत्तर नहीं दे सका । ग्राहक ने कहा कि वह मुझसे थक गई थी कि मैं उसके प्रश्नों का उत्तर नहीं दे पा रहा था और यह एक तरह से हास्यास्पद है । उसने मुझे पिछले काम के लिए धन्यवाद नहीं दिया जो मैंने भी किया था । मैंने उससे कहा कि मैं उसे एक अधिक अनुभवी व्यक्ति दूंगा । मुझे यह समझ में आता है कि मुझे अपनी नौकरी में एक विशेषज्ञ होना चाहिए था । लेकिन मुझे ऐसा कहते हुए सुनकर वास्तव में मेरे आत्मविश्वास को कमजोर कर दिया । मुझे लगा कि मैं कड़ी मेहनत कर रहा था । लेकिन उस क्षण मुझे लगा कि यह अर्थहीन था । मैंने प्रयास किया और मुझे एक नकारात्मक अनुभव और बहुत सारी नकारात्मक भावनाओं से पुरस्कृत किया गया । फोन कॉल के बाद का अनुभव यह था कि मैं दुखी और अभिभूत महसूस कर रहा था. मैं काम के बाद घर चला गया और लगभग हंस - चिल्लाकर रो पड़ा । मुझे दयनीय लगता है कि मैं गुस्से में ग्राहकों को संभाल नहीं पा रहा हूं और मैं दूसरा अनुमान लगा रहा हूं कि क्या यह नौकरी वास्तव में मेरे लिए काम करने वाली है । मुझे नहीं पता कि मुझे इससे क्या चाहिए । कोई भी इसे वैसे भी नहीं पढ़ेगा । - बर्ड | D5: NEGATIVE | E5: 0.97841054 | F5: NEGATIVE | G5: 0.90717733
A6: PO5 | B6: Excuse me ma'am im literally hyperventilating bawling and trembling. Im not using it as an excuse im literally in distress Aaaaand she fired me. | C6: माफ कीजिए मैम मैं सचमुच अति - हवादार और कांप रही हूं । मैं इसे एक बहाने के रूप में उपयोग नहीं कर रही हूं, मैं सचमुच संकट में हूं और उसने मुझे निकाल दिया । | D6: NEGATIVE | E6: 0.99943525 | F6: NEGATIVE | G6: 0.90182137
A7: PO6 | B7: I had really really really horrible PMS today and the advil only worked for about 45 minutes after taking forever to kick in, the pain was returning less than an hour before I had to go in. I had already posted that I was lookign for someone to cover me or trade shifts but noone replied. Its a super casual workplace and very quiet in the winter. The last time I asked for someone to cover my shift but noone came in I went in anyway because I decided I could push through the 0 sleep/exam stress/not taking care of myself, but they weren't expecting me to come in and I was crossed off the schedule. Today I basically decided it'd be the same situation, if I called in it would just be one of the teens I work with who answers anyway and like yea idk and itd probably be fine ?? But I feel so so so so bad about it. I was feeling ok and not out of comission like I had been all day for a good bit of what wouldve been my shift. A coworker I'm befriending was probably super disappointed bc she was working front counter with a kid she finds very annoying. I'm worried I made it so that taking breaks was difficult, what if drivethru or skip the dishes got super busy while someone was on break ?? I feel so fucking selfish. I feel like people are judging me! I wish I contacted someone about it like messaged my manager or soemthing even though I dont think ???? I wouldve needed to I don't know. Noone contacted me ??? I wouldve come in and brought advil with me if they did. I dont know. I dont know. Ive been so guilty and anxious about it I feel like its going to weigh on me until I go into my next shift and either noone comments on it or I have a conversation about it. | C7: मुझे आज वास्तव में वास्तव में भयानक पी. एम. एस. था और एडविल ने हमेशा के लिए काम करने के बाद लगभग 45 मिनट तक काम किया । दर्द एक घंटे से भी कम समय में वापस आ रहा था, इससे पहले कि मुझे अंदर जाना था । मैंने पहले ही पोस्ट कर दिया था कि मुझे किसी को कवर करने के लिए किसी की तलाश थी या व्यापार शिफ्ट में लेकिन किसी ने जवाब नहीं दिया । यह एक बहुत ही अनौपचारिक कार्यस्थल था और सर्दियों में बहुत शांत था । पिछली बार मैंने किसी से अपनी शिफ्ट को कवर करने के लिए कहा था लेकिन कोई भी अंदर नहीं आया, मैं वैसे भी अंदर गया क्योंकि मैंने फैसला किया कि मैं 0 नींद / परीक्षा तनाव से गुजर सकता हूं / अपनी देखभाल नहीं कर रहा था लेकिन वे मुझसे अंदर आने की उम्मीद नहीं कर रहे थे और मुझे अनुसूची से बाहर कर दिया गया था । आज मैंने मूल रूप से फैसला किया कि यह वही स्थिति होगी अगर मैं इसमें कॉल करता तो मैं उन किशोरों में से एक होता जो वैसे भी जवाब देते हैं और जैसे कि हाँ और शायद यह ठीक है? मैं ठीक महसूस कर रहा था और आयोग से बाहर नहीं था जैसे कि मैं सारा दिन अपनी शिफ्ट के लिए रहा होता । एक सहकर्मी जिससे मैं दोस्ती कर रहा था वह शायद बहुत निराश था बी. सी. वह एक बच्चे के साथ फ्रंट काउंटर पर काम कर रही थी जिसे वह बहुत परेशान करती है । मुझे चिंता है कि मैंने इसे बनाया ताकि ब्रेक लेना मुश्किल हो गया । क्या होगा अगर ड्राइवथ्रू या व्यंजनों को छोड़ना बहुत व्यस्त हो जाता है जबकि कोई ब्रेक पर होता है? मैं बहुत स्वार्थी महसूस करता हूं । मुझे लगता है कि लोग मुझे न्याय कर रहे होते हैं । काश मैं इसके बारे में किसी ने मेरे प्रबंधक को संदेश भेजा होता या कुछ ऐसा ही होता जो मुझे नहीं लगता? | D7: NEGATIVE | E7: 0.99780637 | F7: NEGATIVE | G7: 0.91289681
A8: PO7 | B8: hi uhhh. ive had these weird experiences throughout my life that im not entirely sure what to classify as? i am diagnosed with general anxiety but i dont really know if these are considered anxiety attacks. sometimes when i get overwhelmed and upset and start crying i have trouble breathing properly. like hyperventilating i guess?? but im not entirely sure bc its not FAST but its uncontrollable and is kinda like gasps. but the thing is sometimes i dont really think it happens from anxiety?? it happened today at work when my manager *gently* scolded me and that + the stress from the busy day just made me start crying. i guess i was a little anxious but i just felt bad and a little stupid for the mistake i made this doesnt happen every time i cry tho. ive had times ive cried a lot harder than when i have during these and i could control my breathing Actually. i just realized this only happens in social situations ??? i have social anxiety as well (though im doing a lot better than when i was initially diagnosed) i dont remember it happening when im alone ok basically help pls is this normal or is this an anxiety thing | C8: हाय उह. मुझे अपने पूरे जीवन में ऐसे अजीब अनुभव हुए हैं कि मुझे पूरी तरह से यकीन नहीं है कि क्या वर्गीकृत किया जाए क्योंकि मुझे सामान्य चिंता का पता चला है लेकिन मुझे वास्तव में नहीं पता कि इन्हें चिंता के हमले माना जाता है या नहीं. कभी - कभी जब मैं अभिभूत और परेशान हो जाता हूं और रोने लगता हूं तो मुझे ठीक से सांस लेने में परेशानी होती है. जैसे कि मुझे लगता है कि हाइपरवेंटिलेटिंग लेकिन मुझे पूरी तरह से यकीन नहीं है कि बी. सी. यह तेज नहीं है लेकिन यह अनियंत्रित है और थोड़ा हांफ की तरह है. लेकिन बात यह है कि कभी - कभी मुझे वास्तव में नहीं लगता कि यह चिंता से होता है. यह आज काम पर हुआ जब मेरे प्रबंधक ने मुझे फटकार लगाई और उस व्यस्त दिन के तनाव ने मुझे रोना शुरू कर दिया । मुझे लगता है कि मैं थोड़ा चिंतित था लेकिन मुझे बस बुरा महसूस हुआ और गलती के लिए थोड़ा मूर्खता महसूस हुई जब मैंने हर बार रोते समय ऐसा नहीं होता था । वास्तव में. मुझे अभी एहसास हुआ कि यह केवल सामाजिक स्थितियों में होता है? | D8: NEGATIVE | E8: 0.99620408 | F8: NEGATIVE | G8: 0.91866875
A9: PO8 | B9: Hi people of Reddit. Normally I wouldn't find myself in this kind of position to write this but the fact is I don't even know how I should handle this now. I started a new job back in June while I still had another job that I enjoyed. I started to notice that I wasn't able to breath (I have asthma) and I used my inhaler a lot and it didn't help at all. Well anyway after a few doctors visits it turns out my anxiety was getting worse. At first it was mostly not being able to breath and it just kept getting worse. I had to quit the one job that I enjoyed because of reasons with the new manager that had just started working there. Anyway so I started putting myself into my other job working a lot and being helpful picking up other people's hours. I have a bag that I carry my medication around in and they have given me some problems with that as well. So moving on to being there a few months and I just find myself getting worse. My anxiety pretty much taking over my life. My depression starting to get worse again as well. I find myself struggling to get the will to even go to work. When I get there I have the routine of taking my medication with no help. While at work I find myself struggling to even be happy. Everyday the same old thing which isn't the problem then comes rude customers, customers who try to make me feel stupid when they are the one being stupid, customers with stupid jokes, and customers who feel they are entitled. I deal with them as best as I can. Next is the other employees who talk trash about other coworkers. Giving me attitude because I had a doctor's note to work in the least populated area of the store, a head cashier telling another person that I was faking it, and another head cashier saying that everyone has anxiety. Okay YES SUSAN (Her name isn't actually Susan) EVERYONE HAS ANXIETY WHY DON'T YOU TELL ME WHEN YOU HAVE FEEL LIKE YOU'RE DYING OR YOU FEEL LIKE YOU CAN'T BREATH OR WHEN YOU DON'T EVEN FEEL LIKE YOU ARE IN YOUR OWN BODY, I'LL WAIT. Anyway time after time my anxiety keeps getting worse. The area that was least populated now is closed due to it being out of season and I'm working as a front entrance cashier again. All I asked was not to have to go out into the isle and greet the customers. Not that I couldn't help customers or even greet them from behind the counter. They are saying it's apart of my job and it's like I can still greet them from behind the counter. They are giving me a hard time about it but there is also people who have doctors notes to sit down. They don't go to the end of the isle to greet people they sit behind the counter and stand up when a customer comes to check out so why can't I stand behind the counter and occasionally sit down when I have a bad disassociation episode. At this point I don't know what to do. They are being unfair to another cashier with anxiety and me. Anxiety ranges a lot and you should accommodate as long as it doesn't cause undue hardship (which believe me it doesn't). Plus with Covid it's not very smart to greet the customers because that makes me close to then and I could be at higher risk than someone my age. I just don't know what to do anymore everyone there is making so hard, that's why I decided to come to you Reddit users for some advice. &amp;#x200B; Also sorry if this was all over the place, I tend to do that when I'm writing. | C9: नमस्ते रेडिट के लोग । आम तौर पर मैं खुद को इस तरह की स्थिति में नहीं पाता कि मैं इसे लिख पाता, लेकिन तथ्य यह है कि मुझे यह भी नहीं पता कि मुझे इसे कैसे संभालना चाहिए । मैंने जून में एक नई नौकरी शुरू की, जबकि मुझे अभी भी एक और नौकरी थी जिसका मुझे आनंद था । मैंने देखना शुरू किया कि मैं सांस नहीं ले पा रहा था ( मुझे दमा है और मैंने अपने इन्हेलर का बहुत उपयोग किया और इससे कोई मदद नहीं मिली । वैसे भी कुछ डॉक्टरों के जाने के बाद यह पता चला कि मेरी चिंता बढ़ रही थी । पहले तो यह ज्यादातर सांस लेने में सक्षम नहीं था और यह बस बदतर होता गया । मुझे एक नौकरी छोड़नी पड़ी जो मुझे नई प्रबंधक के कारणों से पसंद आई थी जिसने अभी वहां काम करना शुरू किया था । वैसे भी मैंने खुद को बहुत काम करने और अन्य लोगों के घंटों लेने में मददगार होने के लिए अपनी दूसरी नौकरी में डालना शुरू कर दिया । मेरे पास एक थैला है जो मेरे पास है और वे मुझे कुछ समस्याएं दे रहे हैं । इसलिए कुछ महीनों के बाद मैं वहाँ पहुँचता हूँ और मैं खुद को और भी खराब होता देख रहा हूँ । मेरी चिंता मेरे जीवन पर हावी हो रही है । मेरा अवसाद फिर से खराब होने लगा है । मैं खुद को काम पर जाने की इच्छा प्राप्त करने के लिए भी संघर्ष कर रहा हूँ । जब मैं वहाँ पहुँचता हूँ तो मैं बिना किसी मदद के अपनी दवा लेने की दिनचर्या रखता हूँ । जब मैं काम पर होता हूँ तो मैं खुद को खुश रहने के लिए भी संघर्ष कर रहा हूँ । हर दिन वही पुरानी चीज़ जो समस्या नहीं है, वही अशिष्ट ग्राहक आते हैं जो मुझे मूर्खतापूर्ण महसूस कराने की कोशिश करते हैं जब वे मूर्ख होते हैं - मूर्खतापूर्ण चुटकुलों वाले ग्राहक और ग्राहक जो महसूस करते हैं कि वे हकदार हैं । मैं उनके साथ जितना हो सके उतना अच्छा व्यवहार करता हूँ । इसके बाद अन्य कर्मचारी हैं जो अन्य सहकर्मियों के बारे में बेकार बात करते हैं । मुझे ऐसा रवैया देते हुए क्योंकि मेरे पास दुकान के कम से कम आबादी वाले क्षेत्र में काम करने के लिए डॉक्टर का नोट था - एक मुख्य कैशियर किसी अन्य व्यक्ति को यह कहता है कि मैं इसे नकली बना रहा हूं - और एक अन्य प्रमुख कैशियर कहता है कि हर किसी को चिंता है - ठीक है हाँ सुन ( उसका नाम वास्तव में सुसान नहीं है ) - हर किसी को चिंता है - आप मुझे क्यों नहीं बताते जब आप ऐसा महसूस करते हैं जैसे आप मर रहे हैं या आपको ऐसा लगता है कि आप सांस नहीं ले सकते हैं या जब आप कभी ऐसा महसूस नहीं करते हैं जैसे आप अपने शरीर में हैं तो मैं इंतजार करूँगा । मेरे समय के बाद भी मेरी चिंता रहती है कि आप कम से कम बंद होने के कारण बंद हो जाते हैं - मैं फिर से अपने ग्राहकों को घर के सामने से अभिवादन करने के लिए कह रहा हूं कि मैं उन्हें बाहर जाने के लिए कह रहा हूं और मैं उन्हें घर से बाहर जाने के लिए कह रहा हूं कि वे काम कर रहे हैं या मैं उन्हें घर से बाहर जाने के लिए कह रहा हूं । मैं फिर से अपने ग्राहकों को अभिवादन करने के लिए कह रहा हूं कि वे काम करने के लिए बाहर नहीं जा रहे हैं और मैं फिर से बाहर जाने के लिए कह रहा हूं कि मैं उन्हें घर से बाहर जाने के लिए वे मुझे इस बारे में मुश्किल दे रहे हैं लेकिन ऐसे लोग भी हैं जिनके पास बैठने के लिए डॉक्टर के नोट हैं । वे द्वीप के अंत में लोगों का अभिवादन करने के लिए नहीं जाते हैं, वे काउंटर के पीछे बैठते हैं और जब कोई ग्राहक बाहर निकलने के लिए आता है तो खड़े हो जाते हैं, तो मैं काउंटर के पीछे क्यों नहीं खड़ा हो सकता और कभी - कभी बैठ जाता हूं, जब मेरे बीच अलगाव की कोई बुरी घटना होती है । इस समय मुझे नहीं पता कि क्या करना है । वे चिंता के साथ एक अन्य कैशियर के साथ अन्याय कर रहे हैं और मुझे भी । चिंता बहुत अधिक होती है और आपको तब तक समायोजित करना चाहिए जब तक यह अनुचित कठिनाई का कारण नहीं बनता है ( जो मुझे लगता है कि यह नहीं है ) । कोविड के साथ ग्राहकों का अभिवादन करना बहुत चतुराई से नहीं है क्योंकि इससे मैं उस समय के करीब आता हूं और मुझे अपनी उम्र के किसी व्यक्ति की तुलना में अधिक जोखिम हो सकता है । मुझे नहीं पता कि अब और क्या करना है, इसलिए मैं आपको कुछ उपयोगकर्ताओं के लिए आने का फैसला करता हूं । इसके अलावा क्षमा करें अगर यह हर जगह था - जब मैं लिख रहा होता हूँ तो मैं ऐसा करता हूँ । | D9: NEGATIVE | E9: 0.99856299 | F9: NEGATIVE | G9: 0.9132421
A10: PO9 | B10: my parents have always ignored me talking about mental health, i feel like every time i try to express this intense anxiety they invalidate it? “everyone feels this way” maybe that is true but it’s caused me to feel shame when talking about my mental health. i’m so exhausted and think i really do need help. i tried to explain to my doctor about how i was feeling but it felt like they kept trying to brush it off. i don’t feel heard and i almost now feel embarrassed about even talking about it. thankfully they referred me to get counselling but it felt like a shove off? maybe i’m over thinking it. i don’t think it’s normal to feel the way i do but maybe i didn’t explain it correctly. | C10: मेरे माता - पिता ने हमेशा मुझे मानसिक स्वास्थ्य के बारे में बात करते हुए अनदेखा किया है । मुझे लगता है कि हर बार जब मैं इस तीव्र चिंता को व्यक्त करने की कोशिश करता हूं तो वे इसे अमान्य कर देते हैं । शायद यह सच है, लेकिन इससे मुझे शर्म आती है जब मैं अपने मानसिक स्वास्थ्य के बारे में बात कर रहा होता हूं । मैं बहुत थक गया हूं और मुझे लगता है कि मुझे वास्तव में मदद की आवश्यकता है । मैंने अपने डॉक्टर को समझाने की कोशिश की कि मैं कैसा महसूस कर रहा था, लेकिन ऐसा लगा कि वे इसे दूर करने की कोशिश कर रहे हैं । मुझे नहीं सुना गया और मैं लगभग अब इसके बारे में बात करने में भी शर्मिंदा महसूस कर रहा हूं । शुक्र है कि उन्होंने मुझे परामर्श लेने के लिए संदर्भित किया लेकिन ऐसा लगता है कि यह एक झटका है । शायद ऐसा लगता है कि मैं जिस तरह से सोचता हूं वह सामान्य है लेकिन शायद मैंने इसे सही ढंग से समझाया नहीं । | D10: NEGATIVE | E10: 0.99913847 | F10: NEGATIVE | G10: 0.93412614
A11: PO10 | B11: Due to the pandemic, I am currently working 3 jobs after getting laid off back in June on top of going to school. One of them is a retail job. Today I figured out that my bills and expenses outweighed what I had in my account and I was really stressed about it. It crushed me because I pride myself on my own money management. That was the breaking point. This week has been filled with stress from my apartment complex (5 calls and they still haven’t returned my calls...) losing my car keys, neighborhood crime, figuring out how to move, working, and the fact I struggle with many health problems, lead to a very hard few days. Then the money thing was the one that broke the camels back. You could probably see the brokenness in my eyes from a mile away. I have seen a lot about “your best might look a little different today” and let me tell you I was trying to be my best. My best just meant not talking or interacting with others but I was trying my hardest. I was telling myself that as I was trying not to let the stress make me cry. This girl came up to my register. She was around my age (25). She must have seen my eyes because she started talking and conversing with me in a very sincere way. She asked if I was doing okay through the conversation after I said something and then was talking about how it’s one of those rocky days for everyone it seems like. She gave me a little reassuring nod and it was like her telling me “you got this girl” before she walked off and wished me a happy holidays. I am so incredibly grateful for this stranger and her positivity and trying to help me out. Thank you so much. | C11: महामारी के कारण मैं वर्तमान में जून में नौकरी छोड़ने के बाद 3 नौकरियों पर काम कर रहा हूं, स्कूल जाने के अलावा । उनमें से एक खुदरा नौकरी है । आज मुझे पता चला कि मेरे बिल और खर्च मेरे खाते में जो था उससे कहीं अधिक थे और मैं वास्तव में इसके बारे में तनाव में था । इसने मुझे कुचल दिया क्योंकि मुझे अपने स्वयं के धन प्रबंधन पर गर्व है । यह ब्रेक प्वाइंट था । यह सप्ताह मेरे अपार्टमेंट परिसर से तनाव से भरा हुआ है ( 5 कॉल और उन्होंने अभी भी मेरे कॉल वापस नहीं किए हैं... मेरी कार की चाबियाँ खोने से - पड़ोस का अपराध - यह पता लगाना कि काम कैसे करना है और मैं कई स्वास्थ्य समस्याओं से जूझ रहा हूं - कुछ दिनों तक बहुत कठिन हो जाता है । फिर पैसे की चीज ने ऊंटों को तोड़ दिया । आप शायद एक मील दूर से मेरी आंखों में टूटना देख सकते थे । मैंने बहुत कुछ देखा है कि आपका सर्वश्रेष्ठ आज थोड़ा अलग दिख सकता है और मैं आपको बता दूं कि मैं अपना सर्वश्रेष्ठ बनने की कोशिश कर रही थी । मेरा सर्वश्रेष्ठ का मतलब सिर्फ दूसरों के साथ बात करना या बातचीत करना नहीं था, लेकिन मैं अपनी पूरी कोशिश कर रही थी । मैं खुद से कह रही थी कि जब मैं तनाव को मुझे रोने न देने की कोशिश कर रही थी । यह लड़की मेरे रजिस्टर पर आई । वह मेरी उम्र के आसपास थी । उसने मेरी आँखें देखी होंगी क्योंकि उसने मुझसे बहुत ईमानदारी से बात करना और बात करना शुरू कर दिया था । उसने पूछा कि क्या मैं बातचीत के दौरान ठीक हो रही थी जब मैंने कुछ कहा और फिर इस बारे में बात कर रही थी कि यह उन कठिन दिनों में से एक है जो सभी के लिए ऐसा लगता है । उसने मुझे थोड़ा आश्वस्त करने वाला सिर हिलाया और यह कहने जैसा था कि उसने मुझे बताया कि इस लड़की को जाने से पहले आपको मिल गया था और मुझे छुट्टियों की बधाई दी । मैं अविश्वसनीय रूप से आभारी हूं और इस बात के लिए मैं बहुत आभारी हूं । | D11: NEGATIVE | E11: 0.997235 | F11: NEGATIVE | G11: 0.92254025
A12: PO11 | B12: I used to be fine with it. I found always high five another person, give hugs. But yes COVID doesn’t allow me to do those things I still won’t with my family. Like my mom walks up to me and starts playing with my hair and I get very tense. When we pray by holding at dinner, all I can think about it my hands holding my brother and moms. And I can’t stand it. All of my feeling comes out through my hands. I feel like that’s weird to say but. If I get depressed my hands go numb and shaky and I can’t control same goes with anxiety. And when I get mad, whatever is in my hands I just squeeze. And of course sometimes my phone lags out and I get so frustrated that I just squeeze it. And when I touch something and see a sink I wash my hands. Even after showers I wash my hands once or twice. It’s so bothersome. And while I’m typing this (I could just be tired) my hands are numb and shaky (my family does have a line of tremors my mother and brother have it pretty bad) so it could just be tremors? Idk. And also with high fives, if someone it going for a high five I give them a fist bump into their palm. I don’t know why :( I used to not care about these things and over the past months it has changed I did go for a bike ride today. I explored my neighborhood it helped me get rid of the sensitivity in myself for a bit. | C12: मुझे यह कहना अजीब लगता है लेकिन अगर मैं अवसादग्रस्त हो जाता हूं तो मेरे हाथ सुन्न हो जाते हैं और लड़खड़ाते हैं और मैं इसे नियंत्रित नहीं कर पाता हूं तो चिंता होती है । लेकिन हां कोविड मुझे उन चीजों को करने की अनुमति नहीं देता है जो मैं अभी भी अपने परिवार के साथ नहीं कर सकता । जैसे मेरी माँ मेरे पास आती हैं और अपने बालों के साथ खेलना शुरू कर देती हैं और मैं बहुत तनाव में हो जाती हूं । जब हम रात के खाने में प्रार्थना करते हैं तो मैं इसके बारे में सोच सकता हूं कि मेरे हाथ मेरे भाई और माँ को पकड़ते हैं । और मैं इसे बर्दाश्त नहीं कर सकता । मेरा सारा एहसास मेरे हाथों से निकलता है । मुझे ऐसा कहना अजीब लगता है लेकिन. अगर मैं अवसादग्रस्त हो जाता हूं तो मेरे हाथ सुन्न हो जाते हैं और मैं इसे नियंत्रित नहीं कर पाता हूं और चिंता के साथ जाता है. और जब मैं पागल हो जाता हूं तो मेरे हाथों में जो कुछ भी है मैं उसे निचोड़ लेता हूं. और निश्चित रूप से कभी - कभी मेरा फोन लेट जाता है और मैं इतना निराश हो जाता हूं कि मैं उसे निचोड़ लेता हूं. और जब मैं कुछ हाथ छूता हूं तो मैं दो बार हाथ धोता हूं । और जब मैं यह टाइप कर रहा हूँ ( मैं बस थक सकता हूँ ) मेरे हाथ सुन्न और अस्थिर हैं ( मेरे परिवार में कंपन की एक रेखा है, मेरी माँ और भाई के पास यह बहुत बुरा है ) इसलिए यह केवल कंपकंपी हो सकती है । और अगर कोई उच्च पाँच के लिए जाता है तो उच्च पाँच के साथ मैं उनकी हथेली में एक मुट्ठी टक्कर देता हूँ । मुझे नहीं पता कि क्योंः मैं इन चीजों की परवाह नहीं करता था और पिछले महीनों में यह बदल गया है, मैं आज साइकिल की सवारी के लिए गया था । मैंने अपने पड़ोस का पता लगाया, इससे मुझे अपने आप में थोड़ी संवेदनशीलता से छुटकारा पाने में मदद मिली । | D12: NEGATIVE | E12: 0.96710545 | F12: NEGATIVE | G12: 0.93190044
A13: PO12 | B13: I live in an at will state so jobs can fire you at any time for any reason. Ive lost 2 jobs now, about to be a 3rd. And i cant afford to go to the doctor. I want to try to get on disability but when i tried the website said my personal information was wrong.... which just gave me another panic attack. I cant live like this anymore and idk what to do. | C13: मैं अपनी इच्छानुसार रहने की स्थिति में रहता हूं, इसलिए नौकरी किसी भी समय किसी भी कारण से आपको नौकरी से निकाल सकती है । मैंने अब 2 नौकरियां खो दी हैं - लगभग तीसरा होने वाला । और मैं डॉक्टर के पास जाने का जोखिम नहीं उठा सकता । मैं विकलांग होने की कोशिश करना चाहता हूं, लेकिन जब मैंने वेबसाइट पर कोशिश की तो कहा कि मेरी व्यक्तिगत जानकारी गलत थी... जिसने मुझे एक और घबराहट का झटका दिया. मैं अब इस तरह से नहीं रह सकता और मुझे पता है कि क्या करना है । | D13: NEGATIVE | E13: 0.99962223 | F13: NEGATIVE | G13: 0.91120529
... A555: PO554 | B555: Putting this into the void.. I need to get some things off my chest. I dont know what's wrong with me. I'm so fucking tired of being this person. My whole life I've felt off.. I can't remember a time I was really happy, at least for a prolonged period of time. I barely have any memory of my childhood/past. I remember some stories, only ones that I've been told or that I have told to others, but it doesn't feel like I lived them. I feel like I cause all the bad the bad things that happen around me. I don't know how to describe it but it feels like there is something gross and evil in me.. its taking everything from me and everyone around me. And I feel like everyone knows it and hates me for it. When I was 15 my mom committed suicide. I will never forgive myself for my selfishness when she was sick. I blame myself. She did it while my dad was picking me up and we found her when we got home. I was buying ice cream when she was taking her last breath. The last conversation I had with her was a fight over something stupid of course, me being myself. My mom was amazing and nothing like me, except for the mental illness I guess. She was outgoing and loving and intelligent. I can't help but feel like I made her sick. Its hard for me to remember a lot about her because thinking of it is too painful so I try to avoid it.. its always playing in the back of my mind though. I've tried... even when I was younger, like 10/11, I tried therapy but it didn't help. I've been to a lot of therapists off and on since then but nothing has stuck. I started grief counselling this year but there's nothing that can be said that changes the things I'm feeling. I was on SSRIs for 4 years and finally gave up trying with them after being stuck in this cycle for so long. I'm on Wellbutrin now and some of the apathy from SSRIs is gone, but some days I'm too emotional to function. I'm talking hours and hours of sobbing and just overwhelming sadness. I do get out of bed most days now though. Also, it makes me inconsolably horny... I am pathetic!!!! I'm 20 now. I'm in third year of university, I'm going through the motions but it feels empty. I do things I regret constantly. I have a problem with binge drinking until I black out completely and throw up everywhere. Usually someone else cleans it up because I pass out. I'm so tired of being this burden on everyone around me. Theres some sick part of me that loves feeling like this.. I put myself in bad situations that I know I'll regret, like having sex with a stranger that I'm not even attracted to. But something inside is telling me that this is what I deserve, and I believe it. I dont deserve to be happy. The problem is that I want to take care of others so badly and be needed by someone, but it feels like its always the other way around. I am grateful for the amazing people in my life who take care of me and put up with it but I feel like telling them to stop, since nothing they do will ever change who I am and they're wasting their energy. I think I'm losing it. I've been questioning my thoughts and memories and I don't trust myself or my brain anymore. I sleep excessively but feel like I'm never fully awake, just being dragged through life semi-consciously. I lose track of thoughts and words, I can't focus on anything, my mind wanders into nothingness all the time. Is it ever going to change? I've been waiting my whole life for something to shift, or magically click and everything makes sense and I can stop feeling like this but I'm losing hope. There are days where I feel like maybe it will get better but they are few and far between.. and getting fewer. I want to live but not like this. | C555: इसे खालीपन में डालते हुए. मुझे अपनी छाती से कुछ चीजें निकालनी हैं. मुझे नहीं पता कि मेरे साथ क्या हो रहा है. मैं इस व्यक्ति के होने से बहुत थक गया हूं. मेरा पूरा जीवन मैंने उदास महसूस किया है. मुझे वह समय याद नहीं है जब मैं कम से कम लंबे समय तक वास्तव में खुश था. मुझे अपने बचपन / अतीत की शायद ही कोई याद है. मुझे कुछ कहानियाँ याद हैं - केवल वही जो मुझे बताई गई हैं या जो मैंने दूसरों को बताई हैं. लेकिन ऐसा नहीं लगता कि मैंने उन्हें जिया है. मुझे ऐसा लगता है कि मैं अपने आस - पास होने वाली सभी बुरी चीजों का कारण बनता हूं. मुझे इसका वर्णन करना नहीं आता है लेकिन ऐसा लगता है कि मुझ में कुछ घोर और बुराई है. यह मुझसे और मेरे आसपास के सभी लोगों से सब कुछ छीन लेता है. और मुझे लगता है कि हर कोई इसे जानता है और मुझसे नफरत करता है । जब मैं 15 साल की थी तो मेरी माँ ने आत्महत्या कर ली थी । जब मैं बीमार थी तो मैं अपने स्वार्थ के लिए खुद को कभी माफ नहीं करूंगी । मैं खुद को दोषी ठहराती हूं । उन्होंने ऐसा तब किया जब मेरे पिता मुझे उठा रहे थे और जब हम उसे घर पहुंचे तो हमने उसे पाया । जब वह अपनी आखिरी सांस ले रही थी तो मैं आइसक्रीम खरीद रही थी । उनकी आखिरी बातचीत में मैं खुद खुद ही मूर्ख थी । मेरी माँ अद्भुत थी और मेरे जैसी कुछ भी नहीं थी । मुझे लगता है कि मानसिक बीमारी के अलावा । वह बाहर जा रही थी और प्यार करने वाली और बुद्धिमान थी । मैं मदद नहीं कर सकती लेकिन ऐसा महसूस कर सकती कि मैंने उसे बीमार कर दिया है । मेरे लिए उसके बारे में बहुत कुछ याद रखना मुश्किल है क्योंकि इसके बारे में सोचना बहुत दर्दनाक है इसलिए मैं इससे बचने की कोशिश करती हूं. यह हमेशा मेरे दिमाग के पीछे खेलता है । हालांकि यह हमेशा मेरे दिमाग के पीछे खेलता है । मैंने कोशिश की है. जब मैं छोटा था तब भी. जैसे 10/11. मैंने चिकित्सा की कोशिश की लेकिन यह काम नहीं आया. मैं बहुत सारे चिकित्सक के पास गया और तब से कुछ भी नहीं रुका है. मैंने इस साल शोक परामर्श शुरू किया लेकिन ऐसा कुछ भी नहीं कहा जा सकता है जो चीजों को बदल देता है जो मैं महसूस कर रहा हूं । मैं 4 साल तक एस. एस. आर. आई. पर था और अंत में इस चक्र में इतने लंबे समय तक फंसने के बाद उनके साथ कोशिश करना छोड़ दिया । मैं अब वेलब्यूट्रिन पर हूं और एस. एस. आर. आई. की कुछ उदासीनता चली गई है लेकिन कुछ दिन मैं काम करने के लिए बहुत भावुक हूं. मैं घंटों और घंटों की आहट और सिर्फ भारी उदासी की बात कर रहा हूं. मैं अब ज्यादातर दिनों में बिस्तर से बाहर निकलता हूं. यह भी मुझे असहनीय रूप से कामुक बनाता है. मैं दयनीय रूप से विशाल हूँ. मैं अब 20 साल में एक बार फिर से शराब पीने की समस्या से गुजर रहा हूं. मुझे हर जगह पूरी तरह से बुरा लग रहा है. मुझे पूरी तरह से बुरा लग रहा है । आम तौर पर कोई और इसे साफ कर देता है क्योंकि मैं बाहर निकल जाता हूँ. मैं अपने आस - पास के सभी लोगों पर यह बोझ होने से बहुत थक गया हूँ. मेरा कोई बीमार हिस्सा है जो ऐसा महसूस करना पसंद करता है. मैं खुद को बुरी स्थितियों में डाल देता हूँ कि मुझे पता है कि मुझे किसी ऐसे अजनबी के साथ यौन संबंध बनाने का पछतावा होगा जिससे मैं आकर्षित भी नहीं हूँ । लेकिन अंदर की कोई बात मुझे बता रही है कि मैं इसी लायक हूँ और मुझे विश्वास है कि मैं खुश होने का हकदार नहीं हूँ. समस्या यह है कि मैं दूसरों की इतनी बुरी तरह से देखभाल करना चाहता हूँ और किसी को इसकी आवश्यकता है. लेकिन ऐसा लगता है कि यह हमेशा विपरीत होता है. मैं अपने जीवन में उन अद्भुत लोगों के लिए आभारी हूँ जो मेरी देखभाल करते हैं और इसे सहन करते हैं लेकिन मुझे लगता है कि उन्हें रुकने के लिए कहें क्योंकि वे कुछ भी नहीं करते हैं जो कभी भी बदलेंगे कि मैं कौन हूँ और वे अपनी ऊर्जा बर्बाद कर रहे हैं । मुझे लगता है कि मैं इसे खो रहा हूँ. मैं अपने विचारों और यादों पर सवाल कर रहा हूँ और मुझे अब खुद पर या अपने दिमाग पर भरोसा नहीं है. मैं बहुत अधिक सोता हूँ लेकिन महसूस करता हूँ कि मैं कभी भी पूरी तरह से जागता नहीं हूँ. बस जीवन में अर्ध - सचेत रूप से घसीटा जा रहा हूँ. मैं विचारों और शब्दों का ट्रैक खो देता हूँ. मैं किसी भी चीज़ पर ध्यान केंद्रित नहीं कर सकता हूँ. मेरा दिमाग हर समय शून्य में भटकता है. क्या यह कभी बदलने वाला है. मैं अपने पूरे जीवन में कुछ बदलने का इंतजार कर रहा हूँ. या जादुई रूप से क्लिक करता हूँ और सब कुछ समझ में आता है और मैं ऐसा महसूस करना बंद कर सकता हूँ लेकिन मैं उम्मीद खो रहा हूँ. ऐसे दिन हैं जब मुझे लगता है कि यह बेहतर हो जाएगा लेकिन वे कुछ और बहुत दूर हैं. और कम हो रहा है. मैं जीना चाहता हूँ लेकिन इस तरह से नहीं । | D555: NEGATIVE | E555: 0.9991824 | F555: NEGATIVE | G555: 0.94041455

Sheet ENvsHI
C1: model bias + lack of multilingual generalisation
A3: Row Labels | B3: Count of EN_Sentiment_Label | D3: Row Labels | E3: Count of HI_Sentiment_Label
A4: NEGATIVE | B4: 0.86462094 | D4: NEGATIVE | E4: 1
A5: POSITIVE | B5: 0.13537906 | D5: Grand Total | E5: 1
A6: Grand Total | B6: 1

Sheet mBERT_Response
A1: PromptID | B1: English | C1: Hindi | D1: EN_mBERT_Stars | E1: EN_mBERT_StarScore | F1: HI_mBERT_Stars | G1: HI_mBERT_StarScore | H1: EN_mBERT_Sentiment | I1: HI_mBERT_Sentiment
A2: PO1 | B2: So my therapist recommended to me that I should post on reddit. I'm currently 18 but the story starts when I was 16 in the summer of 2019. I live in the UK and it was the day I received my gcses. I did really well in them and I got 8 A*s and 2 As after a year of hard work and effort. I was at my highest point and I couldn't believe it. The day after however, my cousin tragically passed away in a freak accident in Mexico that should never have happened and I was suddenly thrown into a whirlwind of people grieving around me and panic surrounding how they were going to get his body back and many other things. Initially I thought I was doing okay but a week and a half later, I had my first panic attack. It was terrifying, I genuinely thought I was having a heart attack and that I was going to die. This was my first introduction into my hypochondria and anxiety. For the remainder of the summer I was in a constant state of anxiety and panic - struggling to sleep, eat and petrified about death. During the gcses I was also getting close to a girl who was in my year (we'll call her Anna). However during the early summer Anna got with another guy and things died out after she told me we're no longer on things. After things didn't work out with that guy she messaged me again saying that she wanted to reset things with me (little to my knowledge she was also getting close to another guy during this time). When I went back to school I was still suffering from anxiety and panic - I was quite, unable to speak to anyone from how bad it was. During the first 2 weeks, I was getting close with Anna again and eventually we started to go out. Initially things were going good, my anxiety started to die down and I no longer was having panic attacks. However soon the anxiety returned and manifested itself in different ways that weren't as noticeable with paranoia, fear and depressive episodes due to the fact that she wasn't exactly loyal in the past. Eventually with lockdown things started to get bad. She naturally has quite an abrasive personality but it usually was counterbalanced by her more tender side. However that started to change over lockdown and she started to become very toxic towards me - calling me unattractive, not her type, pathetic etc. This carried on and culminated in her out right treating me like shit where she'd refuse to even speak to me if she didn't like the restaurant I took her to on a date. There are way more examples and stories of this that I can give - even the time she sexually assaulted me which I don't want to get into. But I stayed, I loved her and being with her was the thing that helped me stop being constantly an anxious and nervous wreck. I saw her as the person that I went out with at the start not the person she became. Eventually I couldn't bare it anymore and I broke up with her in October but now the skeletons in my closest have opened and all the feelings I had have returned. For the last 2 months I haven't been eating or sleeping well and I've been constantly anxious. I now also borderline have a panic attack whenever I see her at school too. I'm now seeing a therapist but it took a month - I didn't think I needed help, it can be scary but it can honestly be the best decision you can make. I'm more optimistic about things now and I can see the light at the end of the tunnel. | C2: इसलिए मेरे चिकित्सक ने मुझे सलाह दी कि मुझे रेडिट पर पोस्ट करना चाहिए । मैं वर्तमान में 18 साल का हूँ लेकिन कहानी शुरू होती है जब मैं 2019 की गर्मियों में 16 साल का था । मैं यूके में रहता हूँ और यह वह दिन था जब मुझे अपने जी. सी. एस. मिले । मैंने वास्तव में उनमें अच्छा प्रदर्शन किया और मुझे 8 ए. एस. और 2 मिले क्योंकि एक साल की कड़ी मेहनत और प्रयास के बाद । मैं अपने उच्चतम बिंदु पर था और मुझे इस पर विश्वास नहीं हो रहा था । हालांकि अगले दिन मेरे चचेरे भाई का दुखद रूप से मेक्सिको में एक अजीब दुर्घटना में निधन हो गया जो कभी नहीं होना चाहिए था और मुझे अचानक अपने आस - पास शोकाकुल लोगों के बवंडर में फेंक दिया गया था और इस बारे में घबराया गया था कि वे कैसे उसके शरीर को वापस लाने जा रहे थे और कई अन्य चीजें । शुरू में मुझे लगा कि मैं ठीक कर रहा था लेकिन डेढ़ हफ्ते बाद मुझे पहला पैनिक अटैक आया था । मुझे लगा कि वास्तव में मुझे दिल का दौरा पड़ रहा था और यह मेरी पहली चिंता थी कि मैं पहले हायपोक्रिया में मर रहा था । बाकी गर्मियों के लिए मैं लगातार चिंता और घबराहट की स्थिति में था - सोने के लिए संघर्ष कर रहा था - खाने के लिए और मृत्यु के बारे में भयभीत था । जी. सी. एस. ई. के दौरान मैं एक लड़की के करीब भी जा रहा था जो मेरे वर्ष में थी ( हम उसे अन्ना कहेंगे ) । हालाँकि गर्मियों की शुरुआत में एना एक और लड़के के साथ मिल गई और चीजें खत्म हो गईं जब उसने मुझसे कहा कि हम अब चीजों पर नहीं हैं । उस आदमी के साथ चीजें ठीक नहीं होने के बाद उसने मुझे फिर से संदेश भेजा कि वह मेरे साथ चीजों को फिर से सेट करना चाहती है ( मेरे ज्ञान के अनुसार वह इस दौरान दूसरे लड़के के भी करीब हो रही थी ) । जब मैं स्कूल वापस गया तो मैं अभी भी चिंता और दहशत से पीड़ित था - मैं किसी से भी बात करने में असमर्थ था कि यह कितना बुरा था । पहले 2 हफ्तों के दौरान मैं फिर से अन्ना के करीब आ रहा था और आखिरकार हम बाहर जाने लगे । शुरू में मेरी चिंता कम होने लगी थी । लेकिन जल्द ही चिंता वापस आ गई और खुद को अलग - अलग तरीकों से प्रकट कर दिया जो अतीत में बिल्कुल वफादार नहीं होने के कारण डर और अवसादग्रस्तता के साथ ध्यान देने योग्य नहीं थे । आखिरकार लॉकडाउन के साथ चीजें खराब होने लगीं । स्वाभाविक रूप से उनका व्यक्तित्व काफी घर्षक था लेकिन यह आमतौर पर उनके अधिक कोमल पक्ष से असंतुलित था । हालाँकि यह लॉकडाउन के बाद बदलने लगा और वह मेरे प्रति बहुत विषाक्त होने लगी - मुझे अनाकर्षक कहने लगी - अपने प्रकार की दयनीय आदि नहीं । यह जारी रहा और उसके मेरे साथ सही व्यवहार करने में समाप्त हो गया, जहां वह मुझसे बात करने से भी इनकार कर देती थी, अगर वह पसंद नहीं करती थी कि जिस रेस्तरां में मैं उसे डेट पर ले गई थी । इसके और भी उदाहरण और कहानियां हैं जो मैं दे सकती हूं - उस समय भी जब उसने मेरा यौन उत्पीड़न किया था जिसे मैं शामिल नहीं करना चाहती थी । लेकिन मैं उससे प्यार करती थी और उसके साथ रहने से मुझे लगातार चिंतित और घबराए हुए होने से रोकने में मदद मिली । मैंने उसे उस व्यक्ति के रूप में देखा जिसके साथ मैं शुरू में बाहर गई थी न कि वह व्यक्ति जो वह बन गई थी । आखिरकार मैं इसे और बर्फ़ नहीं कर सकी और अक्टूबर में मैंने उसके साथ ब्रेकअप कर लिया, लेकिन अब मेरे सबसे करीबी कंकाल खुल गए हैं और सभी भावनाएँ वापस आ गई हैं । पिछले 2 महीनों से मैं खा नहीं रही हूं या अच्छी तरह से सो नहीं रही हूं और मैं लगातार चिंतित हूं । अब जब भी मैं उसे स्कूल में देखती हूं तो मुझे भी पैनिक अटैक होता है । मैं अब एक चिकित्सक को देख रही हूं लेकिन इसमें एक महीना लग गया - मुझे नहीं लगता था कि मुझे मदद की ज़रूरत है क्योंकि यह डरावना हो सकता है लेकिन यह ईमानदारी से सबसे अच्छा निर्णय हो सकता है । मैं अब चीजों के बारे में अधिक आशावादी हूं और मैं सुरंग के अंत में रोशनी देख सकती हूं । | D2: 2 | E2: 0.34718233 | F2: 2 | G2: 0.39914289 | H2: =IF(D2<=2,"NEGATIVE",IF(D2=3,"NEUTRAL","POSITIVE")) -> NEGATIVE | I2: =IF(F2<=2,"NEGATIVE",IF(F2=3,"NEUTRAL","POSITIVE")) -> NEGATIVE
A3: PO2 | B3: Hey all! I'd like to start this thread to maybe help each other check in on 'filling the cup.' My anxiety embeds itself as relationship anxiety and in-home anxiety, where being home too much makes me intensely anxious, feeling totally empty, useless and lonely. I have a hard time just hanging out (you can imagine what 9 months of COVID has done to me in this regard.) I've started making a daily practice of creating a 'Ways to Fill My Cup' list, so that I feel less empty and anxious. It's helping me A LOT to check out which things make me feel most supported and calm. I make a list starting in the morning and add to it if I do other positive things during the day. Example: Yesterday I had no plans, and the impending day of loneliness at home was looming dark and large. So my "Fill My Cup" list ended up pretty long. On it were things like: Finally doing my dishes, putting on the Chillhop ambient sound spotify playlist which was amazing for my busy mind, unpacking all of my Christmas items which makes my space feel more clean, spending time on my skin and teeth care which I sometimes neglect and then feel bad about, watching one hour of a comforting show, calling one friend, scrubbing neglected kitchen/bathroom spots with clorox wipes, watching funny animal videos, and more. This seems like a normal day of tasking, but since I also have ADHD, I often neglect things or am not consciously 'checked in' to doing them, so it has no impact on my emotional wellbeing. Writing these items down so that I could SEE that my day wasn't totally 'wasted' in 'emptiness' was a huge deal for me. I spent time being productive and also time just being my own friend. Adding to it throughout the day kept me focused on the actual imagery of filling up my cup. My mind stayed relatively calm throughout. Does anyone else engage in a similar practice? If not, do you think it might help you? Let's talk!! | C3: अरे सभी अद्भुत लोग, मैं इस धागे को शुरू करना चाहता हूं ताकि शायद एक - दूसरे को'कप भरने'में मदद मिल सके । मेरी चिंता खुद को रिश्ते की चिंता और घर में चिंता के रूप में जोड़ती है । जहाँ घर में बहुत अधिक होने से मुझे बहुत अधिक चिंता होती है । मैं पूरी तरह से खाली और अकेला महसूस करता हूं । मुझे बस बाहर घूमना मुश्किल होता है ( आप कल्पना कर सकते हैं कि कोविड के 9 महीनों ने इस संबंध में मेरे साथ क्या किया है । मैंने'मेरे कप को भरने के तरीके'की सूची बनाने का दैनिक अभ्यास करना शुरू कर दिया है ताकि मैं कम खाली और चिंतित महसूस करूं । इससे मुझे यह देखने में बहुत मदद मिल रही है कि कौन सी चीजें मुझे सबसे अधिक समर्थित और शांत महसूस कराती हैं । मैं सुबह से एक सूची बनाता हूं और अगर मैं दिन के दौरान अन्य सकारात्मक चीजें करता हूं तो इसमें जोड़ता हूं । उदाहरण के लिएः कल मेरी कोई योजना नहीं थी और घर में अकेलेपन का आने वाला दिन अंधेरा और बड़ा हो रहा था । इसलिए मेरी " मेरे कप को भरें " सूची काफी लंबी हो गई । इस पर कुछ चीजें थीं जैसेः अंत में मेरे व्यंजन बनाना - चिलहॉप परिवेश ध्वनि स्पॉटिफाई प्लेलिस्ट जो मेरे व्यस्त दिमाग के लिए अद्भुत था - मेरी क्रिसमस की सभी वस्तुओं को खोलना जो मेरी जगह को अधिक स्वच्छ महसूस कराता है - मेरी त्वचा और दांतों की देखभाल पर समय बिताना जो मैं कभी - कभी उपेक्षा करता हूं और फिर एक घंटे के आरामदायक शो को देखने के बारे में बुरा महसूस करता हूं - एक दोस्त को बुलाना - उपेक्षित रसोईघर / बाथरूम के धब्बों को स्क्रब करना - क्लोरॉक्स वाइप्स के साथ - साथ मजेदार जानवरों के वीडियो देखना - और बहुत कुछ । यह काम करने का एक सामान्य दिन लगता है लेकिन चूंकि मेरे पास एडीएचडी भी है, इसलिए मैं अक्सर चीजों की उपेक्षा करता हूं या जानबूझकर उनकी जांच नहीं करता हूं - ऐसा करने से मेरी भावनात्मक भलाई पर कोई प्रभाव नहीं पड़ता है । इन वस्तुओं को लिख कर ताकि मैं देख सकूं कि मेरा दिन'खालीपन'में पूरी तरह से'बर्बाद'नहीं हुआ था, यह मेरे लिए एक बहुत बड़ा सौदा था । मैंने उत्पादक होने में समय बिताया और साथ ही समय सिर्फ अपना खुद का दोस्त होने में भी बिताया । पूरे दिन इसके साथ जुड़ने से मेरा ध्यान अपने कप को भरने की वास्तविक कल्पना पर केंद्रित रहा । मेरा मन पूरे समय अपेक्षाकृत शांत रहा । क्या कोई और इसी तरह के अभ्यास में संलग्न है । | D3: 5 | E3: 0.52515966 | F3: 2 | G3: 0.37090734 | H3: =IF(D3<=2,"NEGATIVE",IF(D3=3,"NEUTRAL","POSITIVE")) -> POSITIVE | I3: =IF(F3<=2,"NEGATIVE",IF(F3=3,"NEUTRAL","POSITIVE")) -> NEGATIVE
A4: PO3 | B4: When does it come? I made so many silly posts ruminating about awkwardness talking to her, me not wanting to hang out cuz anxiety that I tried hiding, if I was being weird, if I was texting too much because she didn’t reply on a few, the typical over analyzing. I’m high and I just realized while obviously none of that matters my fear is being vulnerable because entering a relationship is an intimate thing and you are sharing your life with someone special apparently. I’ve never really been in a relationship but I’ve realized I’ve been feeling a loneliness my friends can’t help me with. Just speaking from the heart I guess. | C4: यह कब होता है, मैं उससे अजीबता के बारे में अफवाह करते हुए इतने सारे मूर्ख पोस्ट बनाती हूँ, क्योंकि मैं इस चिंता को छिपाना नहीं चाहती थी कि अगर मैं अजीब हो रही थी तो मैं छिपाने की कोशिश कर रही थी, अगर मैं बहुत अधिक संदेश भेज रही थी क्योंकि उसने कुछ पर जवाब नहीं दिया था, तो सामान्य रूप से अधिक विश्लेषण करना । मैं उच्च हूँ और मुझे एहसास हुआ कि जाहिर है कि इनमें से कोई भी मायने नहीं रखता है कि मेरा डर कमजोर हो रहा है क्योंकि रिश्ते में प्रवेश करना एक अंतरंग बात है और आप अपने जीवन को किसी विशेष व्यक्ति के साथ साझा कर रहे हैं । मैं वास्तव में कभी भी किसी रिश्ते में नहीं रही हूं, लेकिन मुझे एहसास हुआ कि मैं एक अकेलापन महसूस कर रही हूं जिसमें मेरे दोस्त मेरी मदद नहीं कर सकते हैं । बस दिल से बात करते हुए मुझे लगता है । | D4: 2 | E4: 0.33156732 | F4: 2 | G4: 0.36272544 | H4: =IF(D4<=2,"NEGATIVE",IF(D4=3,"NEUTRAL","POSITIVE")) -> NEGATIVE | I4: =IF(F4<=2,"NEGATIVE",IF(F4=3,"NEUTRAL","POSITIVE")) -> NEGATIVE
